Workbook

Sheet Résumé
A1: Tableau de bord du catalogue
A3: =+A22 -> Formations PUI
A4: Catalogue de ressources de l'innovation et l'entrepreneuriat | B4: Date mise à jour | C4: 46294
A5: Formations PUI (fondateurs) | C5: 87
A6: Formations externes | C6: 21
A7: Formateurs par thématiques | C7: 34
A8: Lieux de l'innovation | C8: 21
A9: Equipements | C9: 18
A10: Outils innovation | C10: 62
A11: Bibliographie | C11: 32
A12: Contact Valo | C12: 1
A13: Financements | C13: 21
A14: Se former pour l'avenir | C14: 6
A16: Phase collecte V2 | C16: 1
A21: Définitions
A22: Formations PUI | B22: Formations qui sont dispensées dans au moins un établissement de l'Université Paris Saclay faisant partie des fondateurs PUI
A23: Formations externes | B23: Formations disponibles dans d'autres plateformes ou établissements en dehors du P14
A24: Formateurs | B24: Personnes ressources clé internes ou externes auxquelles nous pourrions faire appel pour la création de contenus et/ou formations
A25: Lieux de l'innovation | B25: Locaux habilités pour réaliser des activités de formation, entrepreneuriat et innovation
A26: Equipements | B26: Equipements et technologies disponibles pour la formation, prototypage, entrepreneuriat, etc
A27: Outils | B27: Supports et outils pratiques (fiches, plaquettes, jeux, …)
A28: Bibliographie | B28: Livres, articles, revues, textes et contenus web utilisés comme référence lors de la recherche pour la conception de la formation

Sheet Formations PUI
A1: Formations
A2: N | B2: Titre de la formation | C2: Objectifs pédagogiques du dispositif | D2: Etablissement | E2: Niveau | F2: Modalités pédagogiques / méthodologie | G2: Format | H2: Durée | I2: Modalité | J2: Public ciblé | K2: Pays | L2: Langue | M2: Coût | N2: web | O2: Contact | P2: Mail | Q2: Localisation | R2: CONTRIBUTEUR
A3: 1 | B3: Master innovation et valorisation de la recherche | C3: Design and implement future-focused innovation strategies that can be applied to any industry. Learn alongside a global cohort of like-minded professionals | D3: Université Paris-Saclay | E3: Master | F3: Cours magistraux, TP | G3: 2 jours par semaine | H3: 1 an | I3: Présentiel | J3: Bac +4 | K3: France | L3: Français- anglais | M3: 6000 | O3: Nicolas Soulié, Anne Plunket | Q3: Faculté Jean Monnet
A4: 1 | B4: Management de la R&D et de l’innovation | C4: Panorama des connaissances (théories et méthodologies) allant de la stratégie de R&D d’une entreprise à l’ingénierie de développement d’une offre de valeur (produit ou service accompagné de son modèle économique) en passant par la définition de roadmaps marchés et technologies, de plans produits, de la maitrise des coûts de R&D et des projets de développement, ainsi que des processus et problématiques d’innovation (incluant la protection de l’innovation, la gestion des compétences, les stratégies de partenariat et d’innovation ouverte). 1. Découvrir tous les étages de l’entreprise innovante : son écosystème, sa stratégie, sa R&D, sa gestion de l’innovation et ses projets de développement de produits / services / modèles économiques nouveaux. 2. Préparer aux métiers de l’innovation et de l’intraprenariat qui sont des métiers récents en France et en Europe : métiers de directeur innovation, manager-ingénieur de l’innovation durable, aux rôles d’interfaces sur la chaine de la valeur (comme responsable projet innovant, responsable du développement de l’innovation ouverte…). 3. Articuler la stratégie de l’entreprise avec les théories et méthodologies du management de l’innovation, du management des technologies, des ingénieries de développement, conception et lancement de produits. | D4: Centrale Supélec | E4: Cours | F4: Cours magistraux, TP | G4: Le cours est composé de 9 séances thématiques de 3h. Chaque séance inclut un TD d’une durée de 30 minutes à 1h30 | I4: Présentiel | J4: Etudiants | K4: France | L4: Français | O4: Bernard Yannou | P4: bernard.yannou@centralesupelec.fr | Q4: Centrale SupElec | R4: Bernard Yannou
A5: 1 | B5: Radical innovation Design | C5: Cet atelier vise à avoir une utilisation poussée de la méthodologie de gestion de projets d’innovation Radical Innovation Design, dans le cadre du lancement d’une start-up dans le domaine de la silver économie. Radical Innovation Design est une méthodologie de gestion de projets d'innovation, made in CentraleSupélec, qui a fait l'objet d'une start-up, d'un jeu sérieux et d'un eBook en accès gratuit (https://doi.org/10.1051/978-2- 7598-3066-4) qui permet d'accéder à de multiples ressources. La méthodologie en elle-même est qualifiable d'ingénierie de l'innovation, car elle introduit de nouveaux concepts, méthodes, et une plateforme informatisée pour poser un problème d'innovation complexe, cibler les zones d'intérêt qui créent de l'utilité pour les usagers et de la profitabilité pour l'entreprise, et "idéer" une solution système et son modèle économique optimaux. Silver Valley, qui est un regroupement d’acteurs qui fédère près de 300 organisations de la Silver Économie - filière transversale qui répond aux besoins et usages des seniors et de leur entourage -, est partenaire de l’atelier. C’est un écosystème unique en Europe qui a pour objectif de préparer la société de la longévité, d’accélérer le développement et la mise sur le marché de solutions innovantes pour favoriser le mieux-vieillir, l’inclusion des personnes et générer croissance et emploi. Silver Valley a notamment développé le dispositif Open Lab : une communauté de seniors, participant à des séances de co-design, de tests et d’expérimentations des solutions portées par les entrepreneurs. CentraleSupélec a participé au développement de Silver Valley, notamment au développement du dispositif d’innovation Scale Up Lab® qui s’inspire de la méthodologie Radical Innovation design® pour sélectionner et accompagner les start-ups dans leur croissance, expérimentation et réseautage. L’atelier consiste à utiliser et améliorer un processus d’étude rapide et systématique d’un potentiel d’innovation dans le domaine de la Silver Economie, en utilisant Radical Innovation Design, l’IA générative (ChatGPT) et toutes les études disponibles sur les activités et situations d’usage des personnes âgées. L’atelier sera centré sur l’obtention de structurations satisfaisantes des activités des seniors, de cartographies de problèmes ou pain points des activités des seniors, qui à leur tour serviront à orienter les concepteurs de solutions nouvelles et start- upers vers le développement de solutions utiles pour « augmenter » l’activité de ces seniors. | D5: Centrale Supélec | E5: Cours | F5: Cours magistraux, TP | G5: L’atelier se compose de 6 séances de 3h. | J5: Etudiants | K5: France | L5: Français | O5: Bernard Yannou | P5: bernard.yannou@centralesupelec.fr | Q5: Centrale SupElec | R5: Bernard Yannou
A6: 1 | B6: CMA design et transitions | D6: Centrale Supélec | F6: Cours magistraux, TP | I6: Présentiel | J6: Etudiants | K6: France | L6: Français | O6: Bernard Yannou | P6: bernard.yannou@centralesupelec.fr | Q6: Centrale SupElec | R6: Bernard Yannou
A7: 1 | B7: Les Midis de l'entrepreneuriat | C7: Créer sa landing page sans savoir coder en 48 heures | D7: Diogale | F7: Animé par Doudou Diof | G7: 45581 | I7: Distanciel | J7: Etudiants DU | K7: France | L7: Français | N7: https://teams.microsoft.com/dl/launcher/launcher.html?url=%2F_%23%2Fl%2Fmeetup-join%2F19%3Ameeting_NGZiZWIzZjctMWE0Yi00YmI4LTk2ZTctNjA5ZGM3NGMwOTgw%40thread.v2%2F0%3Fcontext%3D%257b%2522Tid%2522%253a%252268cdfebb-157b-4846-ba2f-d196a9124ac0%2522%252c%2522Oid%2522%253a%25222aa70631-91e8-4b12-b01e-79459d41d6b5%2522%257d%26anon%3Dtrue&type=meetup-join&deeplinkId=195361cc-271b-4f88-be91-e82a4d57ad9d&directDl=true&msLaunch=true&enableMobilePage=true&suppressPrompt=true | O7: Carole Poiré | P7: carole.poire@universite-paris-saclay.fr | Q7: Paris Saclay | R7: Sophie Dondeyne
A8: 1 | B8: Les Midis de l'entrepreneuriat | C8: Quelle idée pour créer ton entreprise ? | D8: Innowide | F8: Animé par Damien Cuoq | G8: 45588 | I8: Distanciel | J8: Etudiants DU | K8: France | L8: Français | N8: https://teams.microsoft.com/dl/launcher/launcher.html?url=%2F_%23%2Fl%2Fmeetup-join%2F19%3Ameeting_NGZiZWIzZjctMWE0Yi00YmI4LTk2ZTctNjA5ZGM3NGMwOTgw%40thread.v2%2F0%3Fcontext%3D%257b%2522Tid%2522%253a%252268cdfebb-157b-4846-ba2f-d196a9124ac0%2522%252c%2522Oid%2522%253a%25222aa70631-91e8-4b12-b01e-79459d41d6b5%2522%257d%26anon%3Dtrue&type=meetup-join&deeplinkId=195361cc-271b-4f88-be91-e82a4d57ad9d&directDl=true&msLaunch=true&enableMobilePage=true&suppressPrompt=true | O8: Carole Poiré | P8: carole.poire@universite-paris-saclay.fr | Q8: Paris Saclay | R8: Sophie Dondeyne
A9: 1 | B9: Les Midis de l'entrepreneuriat | C9: De l'idée à l'action : concevoir et lancer votre startup | D9: Start in Saclay | G9: 45602 | I9: Distanciel | J9: Etudiants DU | K9: France | L9: Français | N9: https://teams.microsoft.com/dl/launcher/launcher.html?url=%2F_%23%2Fl%2Fmeetup-join%2F19%3Ameeting_NGZiZWIzZjctMWE0Yi00YmI4LTk2ZTctNjA5ZGM3NGMwOTgw%40thread.v2%2F0%3Fcontext%3D%257b%2522Tid%2522%253a%252268cdfebb-157b-4846-ba2f-d196a9124ac0%2522%252c%2522Oid%2522%253a%25222aa70631-91e8-4b12-b01e-79459d41d6b5%2522%257d%26anon%3Dtrue&type=meetup-join&deeplinkId=195361cc-271b-4f88-be91-e82a4d57ad9d&directDl=true&msLaunch=true&enableMobilePage=true&suppressPrompt=true | O9: Carole Poiré | P9: carole.poire@universite-paris-saclay.fr | Q9: Paris Saclay | R9: Sophie Dondeyne
A10: 1 | B10: Les Midis de l'entrepreneuriat | C10: Les conseils pour avoir un pitch convaincant | D10: Association EGEE | G10: 45609 | I10: Distanciel | J10: Etudiants DU | K10: France | L10: Français | N10: https://teams.microsoft.com/dl/launcher/launcher.html?url=%2F_%23%2Fl%2Fmeetup-join%2F19%3Ameeting_NGZiZWIzZjctMWE0Yi00YmI4LTk2ZTctNjA5ZGM3NGMwOTgw%40thread.v2%2F0%3Fcontext%3D%257b%2522Tid%2522%253a%252268cdfebb-157b-4846-ba2f-d196a9124ac0%2522%252c%2522Oid%2522%253a%25222aa70631-91e8-4b12-b01e-79459d41d6b5%2522%257d%26anon%3Dtrue&type=meetup-join&deeplinkId=195361cc-271b-4f88-be91-e82a4d57ad9d&directDl=true&msLaunch=true&enableMobilePage=true&suppressPrompt=true | O10: Carole Poiré | P10: carole.poire@universite-paris-saclay.fr | Q10: Paris Saclay | R10: Sophie Dondeyne
A11: 1 | B11: Les Midis de l'entrepreneuriat | C11: Les outils à connaitre pour son projet d'entreprise | D11: Design Spot | F11: Annimé par Yoann Montenot | G11: 45616 | I11: Distanciel | J11: Etudiants DU | K11: France | L11: Français | N11: https://teams.microsoft.com/dl/launcher/launcher.html?url=%2F_%23%2Fl%2Fmeetup-join%2F19%3Ameeting_NGZiZWIzZjctMWE0Yi00YmI4LTk2ZTctNjA5ZGM3NGMwOTgw%40thread.v2%2F0%3Fcontext%3D%257b%2522Tid%2522%253a%252268cdfebb-157b-4846-ba2f-d196a9124ac0%2522%252c%2522Oid%2522%253a%25222aa70631-91e8-4b12-b01e-79459d41d6b5%2522%257d%26anon%3Dtrue&type=meetup-join&deeplinkId=195361cc-271b-4f88-be91-e82a4d57ad9d&directDl=true&msLaunch=true&enableMobilePage=true&suppressPrompt=true | O11: Carole Poiré | P11: carole.poire@universite-paris-saclay.fr | Q11: Paris Saclay | R11: Sophie Dondeyne
A12: 1 | B12: Les Midis de l'entrepreneuriat | C12: Le modéle économique | D12: Université Paris-Saclay | G12: 45623 | I12: Distanciel | J12: Etudiants DU | K12: France | L12: Français | N12: https://teams.microsoft.com/dl/launcher/launcher.html?url=%2F_%23%2Fl%2Fmeetup-join%2F19%3Ameeting_NGZiZWIzZjctMWE0Yi00YmI4LTk2ZTctNjA5ZGM3NGMwOTgw%40thread.v2%2F0%3Fcontext%3D%257b%2522Tid%2522%253a%252268cdfebb-157b-4846-ba2f-d196a9124ac0%2522%252c%2522Oid%2522%253a%25222aa70631-91e8-4b12-b01e-79459d41d6b5%2522%257d%26anon%3Dtrue&type=meetup-join&deeplinkId=195361cc-271b-4f88-be91-e82a4d57ad9d&directDl=true&msLaunch=true&enableMobilePage=true&suppressPrompt=true | O12: Carole Poiré | P12: carole.poire@universite-paris-saclay.fr | Q12: Paris Saclay | R12: Sophie Dondeyne
A13: 1 | B13: Les Midis de l'entrepreneuriat | C13: Entreprendre en deeptech : défis et opportunités | D13: Start in Saclay | G13: 45630 | I13: Distanciel | J13: Etudiants DU | K13: France | L13: Français | N13: https://teams.microsoft.com/dl/launcher/launcher.html?url=%2F_%23%2Fl%2Fmeetup-join%2F19%3Ameeting_NGZiZWIzZjctMWE0Yi00YmI4LTk2ZTctNjA5ZGM3NGMwOTgw%40thread.v2%2F0%3Fcontext%3D%257b%2522Tid%2522%253a%252268cdfebb-157b-4846-ba2f-d196a9124ac0%2522%252c%2522Oid%2522%253a%25222aa70631-91e8-4b12-b01e-79459d41d6b5%2522%257d%26anon%3Dtrue&type=meetup-join&deeplinkId=195361cc-271b-4f88-be91-e82a4d57ad9d&directDl=true&msLaunch=true&enableMobilePage=true&suppressPrompt=true | O13: Carole Poiré | P13: carole.poire@universite-paris-saclay.fr | Q13: Paris Saclay | R13: Sophie Dondeyne
A14: 1 | B14: Les Midis de l'entrepreneuriat | C14: Aide à la recherche documentaire pour réaliser une étude de marché | D14: Université Paris-Saclay | F14: Animé par Imelda Lemoing | G14: 45686 | I14: Distanciel | J14: Etudiants DU | K14: France | L14: Français | N14: https://teams.microsoft.com/dl/launcher/launcher.html?url=%2F_%23%2Fl%2Fmeetup-join%2F19%3Ameeting_NGZiZWIzZjctMWE0Yi00YmI4LTk2ZTctNjA5ZGM3NGMwOTgw%40thread.v2%2F0%3Fcontext%3D%257b%2522Tid%2522%253a%252268cdfebb-157b-4846-ba2f-d196a9124ac0%2522%252c%2522Oid%2522%253a%25222aa70631-91e8-4b12-b01e-79459d41d6b5%2522%257d%26anon%3Dtrue&type=meetup-join&deeplinkId=195361cc-271b-4f88-be91-e82a4d57ad9d&directDl=true&msLaunch=true&enableMobilePage=true&suppressPrompt=true | O14: Carole Poiré | P14: carole.poire@universite-paris-saclay.fr | Q14: Paris Saclay | R14: Sophie Dondeyne
A15: 1 | B15: Les Midis de l'entrepreneuriat | C15: Débuter sans argent | D15: Graines de conseil | F15: Animé par Bertrand De Saint Viance | G15: 45693 | I15: Distanciel | J15: Etudiants DU | K15: France | L15: Français | N15: https://teams.microsoft.com/dl/launcher/launcher.html?url=%2F_%23%2Fl%2Fmeetup-join%2F19%3Ameeting_NGZiZWIzZjctMWE0Yi00YmI4LTk2ZTctNjA5ZGM3NGMwOTgw%40thread.v2%2F0%3Fcontext%3D%257b%2522Tid%2522%253a%252268cdfebb-157b-4846-ba2f-d196a9124ac0%2522%252c%2522Oid%2522%253a%25222aa70631-91e8-4b12-b01e-79459d41d6b5%2522%257d%26anon%3Dtrue&type=meetup-join&deeplinkId=195361cc-271b-4f88-be91-e82a4d57ad9d&directDl=true&msLaunch=true&enableMobilePage=true&suppressPrompt=true | O15: Carole Poiré | P15: carole.poire@universite-paris-saclay.fr | Q15: Paris Saclay | R15: Sophie Dondeyne
A16: 1 | B16: Les Midis de l'entrepreneuriat | C16: Les étapes de la création d'entreprise | D16: Vallée Sud Grand Paris | F16: Animé par Farrouk Khenoussi | G16: 45700 | I16: Distanciel | J16: Etudiants DU | K16: France | L16: Français | N16: https://teams.microsoft.com/dl/launcher/launcher.html?url=%2F_%23%2Fl%2Fmeetup-join%2F19%3Ameeting_NGZiZWIzZjctMWE0Yi00YmI4LTk2ZTctNjA5ZGM3NGMwOTgw%40thread.v2%2F0%3Fcontext%3D%257b%2522Tid%2522%253a%252268cdfebb-157b-4846-ba2f-d196a9124ac0%2522%252c%2522Oid%2522%253a%25222aa70631-91e8-4b12-b01e-79459d41d6b5%2522%257d%26anon%3Dtrue&type=meetup-join&deeplinkId=195361cc-271b-4f88-be91-e82a4d57ad9d&directDl=true&msLaunch=true&enableMobilePage=true&suppressPrompt=true | O16: Carole Poiré | P16: carole.poire@universite-paris-saclay.fr | Q16: Paris Saclay | R16: Sophie Dondeyne
A17: 1 | B17: Les Midis de l'entrepreneuriat | C17: Le développement et la construction de sa stratégie sur la propriété intelectuelle | D17: INPI | F17: Animé par Sophie Djega Mariadassou | G17: 45728 | I17: Distanciel | J17: Etudiants DU | K17: France | L17: Français | N17: https://teams.microsoft.com/dl/launcher/launcher.html?url=%2F_%23%2Fl%2Fmeetup-join%2F19%3Ameeting_NGZiZWIzZjctMWE0Yi00YmI4LTk2ZTctNjA5ZGM3NGMwOTgw%40thread.v2%2F0%3Fcontext%3D%257b%2522Tid%2522%253a%252268cdfebb-157b-4846-ba2f-d196a9124ac0%2522%252c%2522Oid%2522%253a%25222aa70631-91e8-4b12-b01e-79459d41d6b5%2522%257d%26anon%3Dtrue&type=meetup-join&deeplinkId=195361cc-271b-4f88-be91-e82a4d57ad9d&directDl=true&msLaunch=true&enableMobilePage=true&suppressPrompt=true | O17: Carole Poiré | P17: carole.poire@universite-paris-saclay.fr | Q17: Paris Saclay | R17: Sophie Dondeyne
A18: 1 | B18: Les Midis de l'entrepreneuriat | C18: Accélérateurs et incubateurs : catalyseurs de réussite | D18: Start in Saclay | G18: 45735 | I18: Distanciel | J18: Etudiants DU | K18: France | L18: Français | N18: https://teams.microsoft.com/dl/launcher/launcher.html?url=%2F_%23%2Fl%2Fmeetup-join%2F19%3Ameeting_NGZiZWIzZjctMWE0Yi00YmI4LTk2ZTctNjA5ZGM3NGMwOTgw%40thread.v2%2F0%3Fcontext%3D%257b%2522Tid%2522%253a%252268cdfebb-157b-4846-ba2f-d196a9124ac0%2522%252c%2522Oid%2522%253a%25222aa70631-91e8-4b12-b01e-79459d41d6b5%2522%257d%26anon%3Dtrue&type=meetup-join&deeplinkId=195361cc-271b-4f88-be91-e82a4d57ad9d&directDl=true&msLaunch=true&enableMobilePage=true&suppressPrompt=true | O18: Carole Poiré | P18: carole.poire@universite-paris-saclay.fr | Q18: Paris Saclay | R18: Sophie Dondeyne
A19: 1 | B19: Les Midis de l'entrepreneuriat | C19: Les stratégies commerciales et les techniques de vente | D19: Association EGEE | F19: Animé par Jacques Bonnement | G19: 45742 | I19: Distanciel | J19: Etudiants DU | K19: France | L19: Français | N19: https://teams.microsoft.com/dl/launcher/launcher.html?url=%2F_%23%2Fl%2Fmeetup-join%2F19%3Ameeting_NGZiZWIzZjctMWE0Yi00YmI4LTk2ZTctNjA5ZGM3NGMwOTgw%40thread.v2%2F0%3Fcontext%3D%257b%2522Tid%2522%253a%252268cdfebb-157b-4846-ba2f-d196a9124ac0%2522%252c%2522Oid%2522%253a%25222aa70631-91e8-4b12-b01e-79459d41d6b5%2522%257d%26anon%3Dtrue&type=meetup-join&deeplinkId=195361cc-271b-4f88-be91-e82a4d57ad9d&directDl=true&msLaunch=true&enableMobilePage=true&suppressPrompt=true | O19: Carole Poiré | P19: carole.poire@universite-paris-saclay.fr | Q19: Paris Saclay | R19: Sophie Dondeyne
A20: 1 | B20: Les Midis de l'entrepreneuriat | C20: Accélérer la croissance : les clés pour réussir sa levée de fonds | D20: Start in Saclay | G20: 45749 | I20: Distanciel | J20: Etudiants DU | K20: France | L20: Français | N20: https://teams.microsoft.com/dl/launcher/launcher.html?url=%2F_%23%2Fl%2Fmeetup-join%2F19%3Ameeting_NGZiZWIzZjctMWE0Yi00YmI4LTk2ZTctNjA5ZGM3NGMwOTgw%40thread.v2%2F0%3Fcontext%3D%257b%2522Tid%2522%253a%252268cdfebb-157b-4846-ba2f-d196a9124ac0%2522%252c%2522Oid%2522%253a%25222aa70631-91e8-4b12-b01e-79459d41d6b5%2522%257d%26anon%3Dtrue&type=meetup-join&deeplinkId=195361cc-271b-4f88-be91-e82a4d57ad9d&directDl=true&msLaunch=true&enableMobilePage=true&suppressPrompt=true | O20: Carole Poiré | P20: carole.poire@universite-paris-saclay.fr | Q20: Paris Saclay | R20: Sophie Dondeyne
A21: 1 | B21: Les Midis de l'entrepreneuriat | C21: Les stratégies marketing | D21: Association EGEE | F21: Animé par Jacques Bonnement | G21: 45756 | I21: Distanciel | J21: Etudiants DU | K21: France | L21: Français | N21: https://teams.microsoft.com/dl/launcher/launcher.html?url=%2F_%23%2Fl%2Fmeetup-join%2F19%3Ameeting_NGZiZWIzZjctMWE0Yi00YmI4LTk2ZTctNjA5ZGM3NGMwOTgw%40thread.v2%2F0%3Fcontext%3D%257b%2522Tid%2522%253a%252268cdfebb-157b-4846-ba2f-d196a9124ac0%2522%252c%2522Oid%2522%253a%25222aa70631-91e8-4b12-b01e-79459d41d6b5%2522%257d%26anon%3Dtrue&type=meetup-join&deeplinkId=195361cc-271b-4f88-be91-e82a4d57ad9d&directDl=true&msLaunch=true&enableMobilePage=true&suppressPrompt=true | O21: Carole Poiré | P21: carole.poire@universite-paris-saclay.fr | Q21: Paris Saclay | R21: Sophie Dondeyne
A22: 1 | B22: Les Midis de l'entrepreneuriat | C22: Startups à impact : entreprendre pour un monde meilleur | D22: Start in Saclay | G22: 45770 | I22: Distanciel | J22: Etudiants DU | K22: France | L22: Français | N22: https://teams.microsoft.com/dl/launcher/launcher.html?url=%2F_%23%2Fl%2Fmeetup-join%2F19%3Ameeting_NGZiZWIzZjctMWE0Yi00YmI4LTk2ZTctNjA5ZGM3NGMwOTgw%40thread.v2%2F0%3Fcontext%3D%257b%2522Tid%2522%253a%252268cdfebb-157b-4846-ba2f-d196a9124ac0%2522%252c%2522Oid%2522%253a%25222aa70631-91e8-4b12-b01e-79459d41d6b5%2522%257d%26anon%3Dtrue&type=meetup-join&deeplinkId=195361cc-271b-4f88-be91-e82a4d57ad9d&directDl=true&msLaunch=true&enableMobilePage=true&suppressPrompt=true | O22: Carole Poiré | P22: carole.poire@universite-paris-saclay.fr | Q22: Paris Saclay | R22: Sophie Dondeyne
A23: 1 | B23: Les Midis de l'entrepreneuriat | C23: Entreprendre autrement : les modéles d'entrepreneuriat alternatifs | D23: Start in Saclay | G23: 45791 | I23: Distanciel | J23: Etudiants DU | K23: France | L23: Français | N23: https://teams.microsoft.com/dl/launcher/launcher.html?url=%2F_%23%2Fl%2Fmeetup-join%2F19%3Ameeting_NGZiZWIzZjctMWE0Yi00YmI4LTk2ZTctNjA5ZGM3NGMwOTgw%40thread.v2%2F0%3Fcontext%3D%257b%2522Tid%2522%253a%252268cdfebb-157b-4846-ba2f-d196a9124ac0%2522%252c%2522Oid%2522%253a%25222aa70631-91e8-4b12-b01e-79459d41d6b5%2522%257d%26anon%3Dtrue&type=meetup-join&deeplinkId=195361cc-271b-4f88-be91-e82a4d57ad9d&directDl=true&msLaunch=true&enableMobilePage=true&suppressPrompt=true | O23: Carole Poiré | P23: carole.poire@universite-paris-saclay.fr | Q23: Paris Saclay | R23: Sophie Dondeyne
A24: 1 | B24: Les Midis de l'entrepreneuriat | C24: L'aide au financement pour créer son entreprise | D24: France Active | F24: Animé par Chérif Abbou | G24: 45806 | I24: Distanciel | J24: Etudiants DU | K24: France | L24: Français | N24: https://teams.microsoft.com/dl/launcher/launcher.html?url=%2F_%23%2Fl%2Fmeetup-join%2F19%3Ameeting_NGZiZWIzZjctMWE0Yi00YmI4LTk2ZTctNjA5ZGM3NGMwOTgw%40thread.v2%2F0%3Fcontext%3D%257b%2522Tid%2522%253a%252268cdfebb-157b-4846-ba2f-d196a9124ac0%2522%252c%2522Oid%2522%253a%25222aa70631-91e8-4b12-b01e-79459d41d6b5%2522%257d%26anon%3Dtrue&type=meetup-join&deeplinkId=195361cc-271b-4f88-be91-e82a4d57ad9d&directDl=true&msLaunch=true&enableMobilePage=true&suppressPrompt=true | O24: Carole Poiré | P24: carole.poire@universite-paris-saclay.fr | Q24: Paris Saclay | R24: Sophie Dondeyne
A25: 2 | B25: Les Midis de l'entrepreneuriat | C25: Clôture de la série des webinaires | D25: Alumni | G25: 45812 | I25: Distanciel | J25: Etudiants DU | K25: France | L25: Français | N25: https://teams.microsoft.com/dl/launcher/launcher.html?url=%2F_%23%2Fl%2Fmeetup-join%2F19%3Ameeting_NGZiZWIzZjctMWE0Yi00YmI4LTk2ZTctNjA5ZGM3NGMwOTgw%40thread.v2%2F0%3Fcontext%3D%257b%2522Tid%2522%253a%252268cdfebb-157b-4846-ba2f-d196a9124ac0%2522%252c%2522Oid%2522%253a%25222aa70631-91e8-4b12-b01e-79459d41d6b5%2522%257d%26anon%3Dtrue&type=meetup-join&deeplinkId=195361cc-271b-4f88-be91-e82a4d57ad9d&directDl=true&msLaunch=true&enableMobilePage=true&suppressPrompt=true | O25: Carole Poiré | P25: carole.poire@universite-paris-saclay.fr | Q25: Paris Saclay | R25: Sophie Dondeyne
A26: 3 | B26: Master 1 et 2 en PI, droit du numérique et de l’espace | C26: L’objectif poursuivi au sein de la mention Droit de la propriété intellectuelle, du numérique et de l’espace consiste à former des juristes hautement spécialisés, en veillant à garantir l’adéquation des enseignements dispensés aux besoins de la pratique. Le déroulement de la formation est conçu pour permettre une pré-spécialisation de l’étudiant dès l’année de Master 1, afin de lui conférer, dans un deuxième temps, la possibilité d’opter, parmi un choix étendu de Masters 2, pour la spécialisation la plus conforme a ses affinités. | D26: Université Paris-Saclay | E26: Master 1 et 2 | F26: Cours magistraux, TP | H26: 2 ans | I26: Présentiel | J26: Etudiants | K26: France | L26: Français | O26: Antoine Latreille | P26: antoine.latreille@universite-paris-saclay.fr | Q26: Paris Saclay | R26: Antoine Latreille
A27: 1 | B27: M2 Droit de l’innovation et propriété industrielle | C27: Acquérir l’expertise nécessaire à l’exercice d’une activité professionnelle tournée vers l’innovation et la propriété industrielle, en phase avec la place éminente occupée par les sciences dures au sein du périmètre de l’Université Paris-Saclay. À l’issue de la formation, les étudiants doivent disposer : + de l’ensemble des connaissances théoriques en droit de la propriété industrielle (droit des brevets, droit des dessins et modèles, droit des marques…) et, plus largement, en droit des technologies et de la valorisation des actifs immatériels de l’entreprise (droit de la concurrence, droit des affaires, droit des télécommunications) ; + de connaissances dans les matières techniques, avec une formation pointue en informatique, réseaux et techniques numériques, afin de conférer aux étudiants une compréhension et une maîtrise des outils comme des principes (formation appliquée à l’informatique, connaissance des réseaux…) ; Acquérir les compétences indispensables à l’exercice de sa future profession. À cet égard, l’intervention de professionnels au sein de la formation et le stage obligatoire de trois à six mois garantissent une familiarité de l’étudiant avec la technique contractuelle utilisée en droit de la propriété industrielle, ou dans dans les produits et services numériques.. Les étudiants apprennent également à élaborer des stratégies de propriété intellectuelle, en intégrant dans leur réflexion le coût et la dimension internationale de la protection recherchée. Par ailleurs, la capacité de recherche de l’étudiant se trouve également mise à l’épreuve grâce à la rédaction d’un rapport de recherche. Enfin, les étudiants bénéficient de cours d’anglais juridique spécialisé, leur permettant de se familiariser avec la terminologie propre à ce champ disciplinaire. | D27: Université Paris-Saclay | E27: Master 1 | F27: Cours magistraux, TP | H27: 1 an | I27: Présentiel | J27: Etudiants | K27: France | L27: Français | O27: Antoine Latreille | P27: antoine.latreille@universite-paris-saclay.fr | Q27: Paris Saclay | R27: Antoine Latreille
A28: 1 | B28: M2 Droit de la création et du numérique | C28: Le Master 2 Droit de la création et du numérique (M2 DCN), fondé il y a trois décennies par le Professeur Pierre Sirinelli, est un diplôme pionnier dans l’étude de la confrontation du droit d’auteur aux nouvelles technologies. Il poursuit deux objectifs essentiels : + Offrir une spécialisation en droit d’auteur, saisi dans toutes ses dimensions, y compris les plus contemporaines (logiciels, jeux vidéo, bases de données), + Offrir une spécialisation en droit du numérique (droit des données personnelles, droit des contrats et de la responsabilité, droit pénal spécial des technologies, droit social et TIC). | D28: Université Paris-Saclay | E28: Master 2 | F28: Cours magistraux, TP | H28: 1 an | I28: Présentiel | J28: Etudiants | K28: France | L28: Français | O28: Antoine Latreille | P28: antoine.latreille@universite-paris-saclay.fr | Q28: Paris Saclay | R28: Antoine Latreille
A29: 1 | B29: M2 Droit des activités spatiales et des télécommunications | C29: Le master spécialité Droit des activités spatiales et des télécommunications (M2 DAST) a été créé en 2002 à la demande et avec le soutien des milieux professionnels pour satisfaire des secteurs en pleine expansion demandeurs de diplômés hautement qualifiés. Il représentait alors le premier diplôme au monde associant l’étude du droit de l’espace et des télécommunications. Il s’est depuis ouvert au secteur de l’aéronautique. Le M2 DAST propose une formation professionnalisante, interdisciplinaire et internationale à des étudiants désireux d’intégrer le secteur des technologies stratégiques : l’espace, l’aéronautique, le numérique et la défense. Le master repose sur une pédagogie fondée sur trois piliers. + Formation professionnalisante. Le contenu du Master est conçu en partenariat avec les grandes entreprises et institutions des secteurs de l’espace/aéronautique et des télécommunications/TIC. Les enseignements fondamentaux sont complétés par des séminaires pratiques. Le contact direct et permanent avec le marché du travail est favorisé par une équipe pédagogique majoritairement composée de professionnels (70% des intervenants), des cours dispensés par les futurs employeurs, dans les locaux d’entreprises et d’institutions prestigieuses (50% des cours), des visites et des voyages professionnels en France et à l’étranger, des projets professionnels conduits pour le compte des partenaires du Master, ainsi qu’un réseau international d’anciens étudiants. + Formation interdisciplinaire. La formation répond aux débouchés professionnels en associant le droit à l’étude d’autres disciplines : sciences, ingénierie, économie, gestion et sciences politiques. Le caractère interdisciplinaire de son équipe pédagogique et de ses promotions facilite l’intégration des diplômés au sein des entreprises et des institutions. Cette formation favorise de plus une compréhension rapide et approfondie des dossiers à traiter et une réelle capacité de dialogue avec toutes les composantes, notamment les départements techniques. + Formation internationale. La formation est ouverte sur l’Europe et le monde grâce à ses enseignements combinant une approche nationale et transnationale des problématiques, ses cours dispensés en français et en anglais, son équipe pédagogique multiculturelle (9 nationalités), ses promotions multinationales (le Master 2 a accueilli des étudiants issus de 71 pays) et ses activités à l’international. | D29: Université Paris-Saclay | E29: Master 2 | F29: Cours magistraux, TP | H29: 1 an | I29: Présentiel | J29: Etudiants | K29: France | L29: Français | O29: Antoine Latreille | P29: antoine.latreille@universite-paris-saclay.fr | Q29: Paris Saclay | R29: Antoine Latreille
A30: 1 | B30: M2 Propriété intellectuelle appliquée | C30: L’objectif est de dispenser un enseignement aussi bien théorique que pratique, hautement spécialisé en IP (séminaires de propriété littéraire et artistique, cours de propriété industrielle appliquée en droit des marques et des brevets, etc.) comme en IT (droit social et TIC, droit des données personnelles, pratique contractuelle spécialisée). L’équipe pédagogique est composée d’enseignants-chercheurs et de professionnels du secteur. Les étudiants sont aptes, dès l’obtention de leur diplôme, à occuper des postes à responsabilité dans le secteur de l’IP/IT. | D30: Université Paris-Saclay | E30: Master 2 | F30: Cours magistraux, TP | H30: 1 an | I30: Présentiel | J30: Etudiants | K30: France | L30: Français | O30: Antoine Latreille | P30: antoine.latreille@universite-paris-saclay.fr | Q30: Paris Saclay | R30: Antoine Latreille
A31: 1 | B31: M2 Propriété intellectuelle et droit des affaires numériques | C31: Le Master 2 Propriété intellectuelle et droit des affaires numériques (M2 PIDAN) forme les étudiants à maîtriser les défis juridiques actuels et futurs liés à l’essor des technologies de l’information, s’agissant aussi bien des enjeux théoriques que des pratiques contractuelles, judiciaires et techniques du secteur, afin de répondre à une demande croissante de la pratique contemporaine du droit des affaires national, européen et international. Les étudiants apprennent à identifier les stratégies juridiques de valorisation du patrimoine « numérique » et « intellectuel » des entreprises.A cette fin, le programme des séminaires allie enseignements fondamentaux en droit des affaires et cours spécialisés en propriété intellectuelle et droit du numérique. La formation met également l'accent sur l'acquisition de connaissances interdisciplinaires complémentaires en informatique et en économie notamment, ainsi que sur des enseignements dispensés en anglais. Selon le projet professionnel, les étudiants ont le choix, grâce aux options et aux travaux personnels, de renforcer leur spécialité soit en droit de la propriété intellectuelle soit en droit du numérique.Ce M2 permet de développer les compétences indispensables à une pratique professionnelle performante pour une insertion professionnelle rapide grâce au stage et aux exercices pratiques (négociation de contrats ou la rédaction de jeux d'écriture, participation aux concours de plaidoiries notamment).Ce Master 2 prépare également à une poursuite d'étude en doctorat en insistant sur la formation à la recherche individuelle (élaboration d'un mémoire de recherche de fin d'étude) et collective à l'occasion de chaque séminaire. Une attention particulière est portée à la maîtrise des outils de recherche et notamment des bases de données juridiques ainsi qu'à la participation à de nombreuses manifestations scientifiques.
A32: 1 | B32: M2 Propriété intellectuelle fondamentale et technologies numériques | C32: Le Master 2 / LLM Propriété intellectuelle fondamentale et technologies numériques (M2/LLM PIFTN) s’intègre dans l’offre de formation complémentaire de la mention Droit de la propriété intellectuelle et du numérique. Il en constitue le parcours international, grâce à un double partenariat, avec l’Université Laval (Québec) et avec l’Université Autonome de Madrid (Espagne). L’objectif est de former des juristes ayant des compétences pointues en Intellectual Property / Information Technology (IP/IT), donc à la fois en droit de la propriété intellectuelle, mais aussi en droit du numérique, dans une perspective résolument européenne et internationale. La formation débouche sur la délivrance, à l’issue d’une année d’étude, d’un double diplôme : un M2 de l’Université Paris-Saclay et un LLM de l’Université Laval (Québec) ou de l’Université Autonome de Madrid (Espagne), grâce à une mobilité étudiante (semestre 1 en France, semestre 2 au Québec ou en Espagne avec convention de reconnaissance mutuelle pour la moitié du programme). Le paiement des droits universitaires (sans surcoût) se fait dans le pays d’inscription initiale pour l’année entière. | D32: Université Paris-Saclay | E32: Master 2 | F32: Cours magistraux, TP | H32: 1 an | I32: Présentiel | J32: Etudiants | K32: France | L32: Français | O32: Antoine Latreille | P32: antoine.latreille@universite-paris-saclay.fr | Q32: Paris Saclay | R32: Antoine Latreille
A33: 1 | B33: FIE | C33: Filière Innovation-Entrepreneurs © (FIE) forme les élèves à entreprendre et innover grâce à une pédagogie par projet. 11 000 m2 dédiés à l'innovation et à l'entrepreneuriat technologique en photonique au Bâtiment 503. | D33: IOGS | E33: élèves avec la vision entrepreneur | H33: 1 à 4 ans | I33: Présentiel | J33: Etudiants | K33: France | L33: Français | O33: David Olivier Bouchez | P33: david-olivier.bouchez@institutoptique.fr | Q33: IOGS | R33: David Olivier Bouchez
A34: 1 | B34: Intelligence et Sécurité économiques | C34: Formation thématique | D34: SATT Paris Saclay | E34: Etudiants (Master, Doctorants) Chargé d'affaires valorisation Chercheurs Start-up PME/ETI | F34: Dispensée dans le Parcours Valo. La formation est enseignée sur demande / chaque thématique peut durer entre 1 heure et 4 heures | G34: Elle peut durer entre 1 heure et 4 heures | I34: Présentiel ou Distanciel | J34: Etudiants (Master, Doctorants) Chargé d'affaires valorisation Chercheurs Start-up PME/ETI | K34: France | L34: Français | O34: Stéphanie Oger-Roussel | P34: stephanie.oger-roussel@satt-paris-saclay.fr | Q34: SATT Paris Saclay | R34: Stéphanie Oger-Roussel
A35: 1 | B35: Veilles et renseignements | C35: Formation thématique | D35: SATT Paris Saclay | E35: Etudiants (Master, Doctorants) Chargé d'affaires valorisation Chercheurs Start-up PME/ETI | F35: La formation est enseignée sur demande / chaque thématique peut durer entre 1 heure et 4 heures | G35: Elle peut durer entre 1 heure et 4 heures | I35: Présentiel ou Distanciel | J35: Etudiants (Master, Doctorants) Chargé d'affaires valorisation Chercheurs Start-up PME/ETI | K35: France | L35: Français | O35: Stéphanie Oger-Roussel | P35: stephanie.oger-roussel@satt-paris-saclay.fr | Q35: SATT Paris Saclay | R35: Stéphanie Oger-Roussel
A36: 1 | B36: Open-innovation | C36: Formation thématique | D36: SATT Paris Saclay | E36: Etudiants (Master, Doctorants) Chargé d'affaires valorisation Chercheurs Start-up PME/ETI | F36: La formation est enseignée sur demande / chaque thématique peut durer entre 1 heure et 4 heures | G36: Elle peut durer entre 1 heure et 4 heures | I36: Présentiel ou Distanciel | J36: Etudiants (Master, Doctorants) Chargé d'affaires valorisation Chercheurs Start-up PME/ETI | K36: France | L36: Français | O36: Stéphanie Oger-Roussel | P36: stephanie.oger-roussel@satt-paris-saclay.fr | Q36: SATT Paris Saclay | R36: Stéphanie Oger-Roussel
A37: 1 | B37: Marketing de l'innovation | C37: Formation thématique | D37: SATT Paris Saclay | E37: Etudiants (Master, Doctorants) Chargé d'affaires valorisation Chercheurs Start-up PME/ETI | F37: La formation est enseignée sur demande / chaque thématique peut durer entre 1 heure et 4 heures | G37: Elle peut durer entre 1 heure et 4 heures | I37: Présentiel ou Distanciel | J37: Etudiants (Master, Doctorants) Chargé d'affaires valorisation Chercheurs Start-up PME/ETI | K37: France | L37: Français | O37: Stéphanie Oger-Roussel | P37: stephanie.oger-roussel@satt-paris-saclay.fr | Q37: SATT Paris Saclay | R37: Stéphanie Oger-Roussel
A38: 1 | B38: Propriété intellectuelle | C38: Formation thématique | D38: SATT Paris Saclay | E38: Etudiants (Master, Doctorants) Chargé d'affaires valorisation Chercheurs Start-up PME/ETI | F38: La formation est enseignée sur demande / chaque thématique peut durer entre 1 heure et 4 heures | G38: Elle peut durer entre 1 heure et 4 heures | I38: Présentiel ou Distanciel | J38: Etudiants (Master, Doctorants) Chargé d'affaires valorisation Chercheurs Start-up PME/ETI | K38: France | L38: Français | O38: Stéphanie Oger-Roussel | P38: stephanie.oger-roussel@satt-paris-saclay.fr | Q38: SATT Paris Saclay | R38: Stéphanie Oger-Roussel
A39: 1 | B39: Transfert de technologie | C39: Formation thématique | D39: SATT Paris Saclay | E39: Etudiants (Master, Doctorants) Chargé d'affaires valorisation Chercheurs Start-up PME/ETI | F39: La formation est enseignée sur demande / chaque thématique peut durer entre 1 heure et 4 heures | G39: Elle peut durer entre 1 heure et 4 heures | I39: Présentiel ou Distanciel | J39: Etudiants (Master, Doctorants) Chargé d'affaires valorisation Chercheurs Start-up PME/ETI | K39: France | L39: Français | O39: Stéphanie Oger-Roussel | P39: stephanie.oger-roussel@satt-paris-saclay.fr | Q39: SATT Paris Saclay | R39: Stéphanie Oger-Roussel
A40: 1 | B40: Business plan | C40: Formation thématique | D40: SATT Paris Saclay | E40: Etudiants (Master, Doctorants) Chargé d'affaires valorisation Chercheurs Start-up PME/ETI | F40: La formation est enseignée sur demande / chaque thématique peut durer entre 1 heure et 4 heures | G40: Elle peut durer entre 1 heure et 4 heures | I40: Présentiel ou Distanciel | J40: Etudiants (Master, Doctorants) Chargé d'affaires valorisation Chercheurs Start-up PME/ETI | K40: France | L40: Français | O40: Stéphanie Oger-Roussel | P40: stephanie.oger-roussel@satt-paris-saclay.fr | Q40: SATT Paris Saclay | R40: Stéphanie Oger-Roussel
...

Sheet Formations Externes
A1: Formations externes
A2: N | B2: Titre de la formation | C2: Objectifs pédagogiques du dispositif | D2: Etablissement | E2: Niveau | F2: Modalités pédagogiques / méthodologie | G2: Format | H2: Durée | I2: Modalité | J2: Public ciblé | K2: Pays | L2: Langue | M2: Coût | N2: web | O2: Contact | P2: Mail | Q2: Localisation | R2: CONTRIBUTEUR
A3: 1 | B3: Enseigner avec le jeu | C3: Découvrez la manière dont les jeux peuvent servir d’agents pivots pour l’engagement des apprenants et l’acquisition de compétences. | D3: Fun mooc Unicamp | E3: Micro certification | F3: On line | G3: 3 semaines | H3: 12 heures | I3: 10 h asynchrones, 2 h synchrones | J3: Aucun pré requis | K3: France | L3: Français | M3: 480 | N3: https://www.fun-mooc.fr/fr/cours/enseigner-avec-le-jeu/ | O3: Jérôme Legrix-Pagès | Q3: Université de Caen Normandie
A4: 2 | B4: Développer la posture entrepreneuriale | C4: Venez découvrir comment établir un plan d'action utile à l'atteinte de votre objectif de vous lancer avec la bonne posture dans votre projet d'entreprise ! | D4: Fun mooc Unicamp | E4: Micro certification | F4: On line | G4: 4 semaines | H4: 20 heures | I4: Asynchrone | J4: Aucun pré requis | K4: France | L4: Français | M4: 250 | N4: https://www.fun-mooc.fr/fr/cours/developper-la-posture-entrepreneuriale/ | O4: Armelle Basquin Marit | Q4: Université de Lille et du Littoral Côte d’Opale, Hubhouse et PEPITE.
A5: 3 | B5: Scénariser un parcours d'apprentissage | C5: Scénarisez votre enseignement pour gagner en cohérence pédagogique et permettre l'atteinte des objectifs fixés. | D5: Fun mooc Unicamp | E5: Micro certification | F5: On line | G5: 7 semaines | H5: 10 heures | I5: Asynchrone | J5: Aucun pré requis | K5: France | L5: Français | M5: 500 | N5: Scénariser un parcours d'apprentissage - Cours - FUN MOOC (fun-mooc.fr) | O5: Morgane Almerge, Michaël Canu | Q5: Université de Perpignan Via Domitia
A6: 4 | B6: Se former à la ludopédagogie | C6: Venez vous former à la ludopédagogie, découvrir l’utilisation du jeu dans un contexte de formation et comment l’intégrer. | D6: Fun mooc Unicamp | E6: Micro certification | F6: On line | G6: 6 semaines | H6: 30 heures | I6: 27 h asynchrones et 3 h synchrones | J6: Aucun pré requis | K6: France | L6: Français | M6: 750 | N6: https://www.fun-mooc.fr/fr/cours/se-former-a-la-ludopedagogie/ | O6: Jérôme Legrix-Pagès | Q6: Université de Caen Normandie
A7: 5 | B7: Oxford Venture Builder | C7: programme for all members of the University of Oxford - including students, staff, faculty members and researchers - who are looking to develop their business ideas, whether individually or as a team. | D7: Oxford | E7: Short programme | F7: On site. Three-day in-person bootcamp, Weekly sessions and mentorship, each Wednesday for five weeks, You will be invited to attend after hours sessions on various business-related topics. During this period, you will be matched with mentors to help you develop your ideas and tackle your challenges. Pitching night, pitch your ideas to our network. This is also a chance to access further support or funding. | G7: 5 semaines | J7: Aucun pré requis | K7: England | L7: English | M7: Gratuit | N7: https://www.sbs.ox.ac.uk/research/centres-and-initiatives/entrepreneurship-centre/oxford-venture-builder | O7: Oxford Saïd Entrepreneurship Centre _ EnSpire Oxford
A8: 6 | B8: Fabriquer l'innovation | C8: Comment se fabrique concrètement l’innovation, et en particulier l’innovation de rupture ? Ce Mooc mobilise des objets des collections du Musée des arts et métiers pour faire comprendre les processus de l’innovation. | D8: CNAM | E8: MOOC | F8: Ce cours est en accès libre. Il ne propose ni forum ni animation et ne délivre pas d'attestation, de badge ou de certificat. | G8: 5 semaines | H8: 8 heures | I8: Rythme: ~1h30/semaine | J8: Aucun pré requis | K8: France | L8: Français | M8: Gratuit | N8: https://www.fun-mooc.fr/fr/cours/fabriquer-linnovation/ | O8: FUN MOOC | Q8: CNAM
A9: 7 | B9: Intelligence artificielle pour et par les enseignants | C9: Explorer et soutenir l'utilisation éclairée de l'IA dans l'éducation. | D9: INRIA | E9: MOOC | F9: Dans le cadre du projet européen AI4T Artificial Intelligence for teachers | G9: 1 semaine | H9: 3 heures | J9: Aucun pré requis | K9: France | L9: Français | M9: Gratuit | N9: https://www.fun-mooc.fr/fr/cours/intelligence-artificielle-pour-et-par-les-enseignants-ai4t/
A10: 8 | B10: Travailler dans un fablab | C10: Habilitation pour travailler dans les machines du FABLAB CN2 de la Cité des Sciences | D10: Cité des Sciences | E10: Initiation et habilitation | F10: Ouverture du FABLAB en OpenLab Les mardis, mercredis, vendredis & samedis (hors vacances scolaires) Les mardis, mercredis, jeudis, vendredis & samedis (pendant vacances scolaires) de 14h30 à 17h30 Les initiations (Laser et Brodeuse) se font les mercredis et samedis à partir de 10h30 Pour les initiations 3D, merci de nous envoyer un email et de nous expliquer votre projet. Un jour et une heure de formation vous sera transmis après analyse de votre besoin. Les habilitations (Laser, 3D et Brodeuse) se font les vendredis à partir de 10h30 Les réservations des machines (avec habilitations) se font pendant les OpenLab | G10: 1 jour | H10: 3 heures | I10: Présentiel selon programmation | J10: Aucun pré requis | K10: France | L10: Français | M10: Gratuit | N10: https://carrefour-numerique.cite-sciences.fr/#!/ | O10: CITE DES SCIENCES | P10: https://mon-compte.cite-sciences.fr/inscription?origin=fabmanager | Q10: LA VILLETTE
A11: 9 | B11: Master PIC projet, innovation conception | C11: Le Master PIC s’articule autour de cinq grandes composantes qui incarnent à la fois son originalité et sa vocation : Le Projet de Master: une situation d’innovation concrète en entreprise où l’étudiant est intégré tout au long du cursus en temps réel Le tutorat: un dispositif pédagogique tripartite entre l’étudiant, un tuteur enseignant et le tuteur entreprise pour permettre d’articuler de manière continue les concepts théoriques et l’expérience pratique Des enseignements: sur les théories et méthodes toutes orientées sur l’innovation : projet, organisation, stratégie, financement, design, créativité, marketing,… Une expérience internationale, à la découverte d’un écosystème d’innovation dans un pays particulièrement emblématique en terme d’innovation Un cycle de visites industrielles, montrant la réalité de l’innovation, de la créativité à la production et la distribution, au sein de l’écosystème français. | D11: Ecole Politechnique | F11: La pédagogie combine des formats variés: cours magistral, étude de cas, pédagogie active, serious game, atelier, challenge, conférence, témoignage de praticiens, etc. | G11: 1 an | H11: Plein temps | I11: Présentiel. Learning by doing | K11: France | L11: Français | N11: https://masterpic.fr/cursus/programme/
A12: 10 | B12: OI iNanoTheRad | C12: Assemblée générale OI iNanoTheRad - 11 février 2025 - Villejuif L’Assemblée Générale d’iNanoTheRad aura lieu le 11 février 2025 de 10h à 12h à Gustave Roussy. Au programme, une présentation d’iNanoTheRad suivie de discussions thématiques sur les innovations en radiothérapie. | D12: Université Paris-Saclay
A13: 11 | B13: ICURe | C13: The Innovate UK ICURe Programme gives researchers the chance to turn ground-breaking research into investment-ready spin-out companies and license agreements. | D13: Innovate UK | F13: We provide funding and personalised support to test the commercial potential of an idea – while enabling researchers take their first steps into the world of business. | G13: 4 stages | H13: Au fil de l'eau | K13: UK | L13: English | N13: https://iuk-business-connect.org.uk/programme/icure/
A14: 12 | B14: investin.paris saclay | C14: Chef d’entreprise, un métier ? | D14: Le 30 | G14: Atelier | K14: France | L14: Français | N14: Chef d’entreprise, un métier ? – Communauté d'agglomération Paris-Saclay | O14: Pierre Henri MULTON | ASPASIE | P14: le30@paris-saclay.fr
A15: 13 | B15: Techinnov | C15: Les acteurs de l’innovation se réunissent autour de rendez-vous d’affaires le 27 mars 2025 au Parc Floral de Paris | D15: CCI Essonne CCI Ile de France | E15: Seminaire | F15: Hybride | G15: 1 jour | H15: JEUDI 27 MARS 2025 - PARC FLORAL DE PARIS | K15: France | L15: Français | N15: Techinnov 2025 | Une journée 100% business & innovation
A16: 14 | B16: MIT | C16: Free online courses from Massachusetts Institute of Technology | D16: USA | E16: MOOC | F16: MITx courses embody the inventiveness, openness, rigor and quality that are hallmarks of MIT, and many use materials developed for MIT residential courses in the Institute's five schools and 33 academic disciplines. Browse MITx courses below. | G16: On line | H16: Au fil de l'eau | K16: USA | L16: English | N16: https://www.edx.org/school/mitx
A17: 15 | B17: HARVARD | C17: Free online courses from Harvard | D17: USA | E17: MOOC | F17: 551 online free courses from Harvard | G17: On line | H17: Au fil de l'eau | K17: USA | L17: English | N17: https://pll.harvard.edu/catalog
A18: 16 | B18: HEC | C18: Free online courses from HEC | D18: France | E18: MOOC | F18: Nombreux cours gratuits et payants pour obtention d'un certificat | G18: On line | H18: Au fil de l'eau | K18: France | L18: Français | N18: https://www.hec.edu/fr/programmes-online/moocs
A19: 17 | B19: POLYTECHNIQUE | C19: Free online courses from Ecole Polytechnique | D19: France | E19: MOOC | F19: Présentation des cours en ligne gratuits et ouverts à tous de l'Ecole polytechnique | G19: On line | H19: Au fil de l'eau | K19: France | L19: Français | N19: https://www.polytechnique.edu/teaching-learning/
A20: 18 | B20: BPI France | C20: Les deeptech plateforme de formations | D20: France | E20: MOOC | F20: Développer ses compétences avec BPI France. Bpifrance Université vous accompagne ! L’entrepreneur ne doit jamais cesser d’apprendre tout au long de son parcours. Les objectifs ? Comprendre ses associés et ses équipes, rester à jour dans son domaine d’expertise, acquérir une nouvelle compétence clé pour le projet, comprendre ses partenaires… | G20: On line | H20: Au fil de l'eau | K20: France | L20: Français | N20: Se former à l’entrepreneuriat deeptech
A21: 19 | B21: AUNEGE Université Numérique | C21: Cours en ligne formation entrepreneuriat | D21: France | E21: MOOC | F21: La plate-forme Moodle de l'Université Numérique est un lieu de mutualisation de ressources éducatives libres. | G21: On line | H21: Au fil de l'eau | K21: France | L21: Français | N21: https://luniversitenumerique.fr/ressources/fun-ressources/
A22: 20 | B22: Réseau CURIE | C22: La journée des sensibilisateurs | D22: France | E22: Journée | F22: ÉDITION 2026 : Et si l'impact était la meilleure porte d'entrée vers la valorisation ? Sensibiliser autrement, détecter plus tôt. | G22: Présentiel | H22: Annuel | K22: France | L22: Français | N22: La journée des sensibilisateurs | Réseau C.U.R.I.E.
A23: 21 | B23: COURSERA | C23: Cours en ligne | D23: USA | E23: Variable | F23: Diférentes thématiques | G23: On line | H23: Au fil de l'eau | K23: USA | L23: English | N23: https://www.coursera.org/courseraplus/?utm_content=ad_b2c_emea_24-11_coursera-plus_fr-local_gg_fr_fr&utm_medium=sem&utm_source=gg&utm_campaign=b2c_emea_x_coursera_ftcof_courseraplus_cx_dr_bau_gg_sem_pr_fr_fr_m_hyb_24-11_x&campaignid=21962872997&adgroupid=172152784478&device=c&keyword=coursera&matchtype=e&network=g&devicemodel=&creativeid=723451402783&assetgroupid=&targetid=kwd-36262515261&extensionid=&placement=&gad_source=1&gad_campaignid=21962872997&gbraid=0AAAAADdKX6YTJ6uaPeGy9Rc6NYUuHMDzM&gclid=Cj0KCQjw54nRBhDCARIsAMcY_SDTW7KIMyFXNQE48TIaiUqif04XJ81SyKLJK1Nuu8IWfhP3BOGMueEaAg0QEALw_wcB
A24: 22
A25: 23

Sheet Formateurs
A1: Formateurs et autres ressources
A2: N | B2: Type | C2: Description | D2: Modalités pédagogiques / méthodologie | E2: Etablissement | F2: Fonction | G2: Type | H2: Nom Contact | I2: Mail | J2: Site Web | K2: Rôle PUI | L2: CONTRIBUTEUR
A3: 1 | B3: Droit des contrats | C3: Parcours Valo. Formation en propriété intellectuelle et contrats de recherche | E3: Université Paris-Saclay | F3: Responsable Pôle Partenariat Valorisation (PPV) DIREV / enseignante master | G3: Interne | H3: Soizic Lefeuvre, Camille Quenec | I3: soizic.lefeuvre@universite-paris-saclay.fr | K3: Fondateur
A4: 2 | B4: Sensibilisation à la PI | C4: Parcours Valo | D4: module théorique et cas pratique | E4: Université Paris-Saclay | F4: DIREV, juristes - agents formateurs | G4: Interne | H4: Salomé Petroff, Charlotte Guerel | I4: camille.queinnec@universite-paris-saclay.fr | J4: https://www.universite-paris-saclay.fr/parcours-de-formation-valorisation-de-projets-de-recherche-innovants-du-concept-au-marche | K4: Fondateur | L4: CQ
A5: 3 | B5: Transferts de technologies | C5: Parcours Valo | D5: module théorique et cas pratique | E5: Université Paris-Saclay | F5: DIREV, chargés affaires - agents formateurs | G5: Interne | H5: Antoine Brian, Elisa Paredes | I5: camille.queinnec@universite-paris-saclay.fr | J5: https://www.universite-paris-saclay.fr/parcours-de-formation-valorisation-de-projets-de-recherche-innovants-du-concept-au-marche | K5: Fondateur | L5: CQ
A6: 4 | B6: Autres modules Parcours Valo | C6: Parcours Valo | D6: module théorique et cas pratique | E6: Université Paris-Saclay | F6: personnels du CERDI, de la SATT, d'IncubAlliance, du Design Spot, | G6: Interne | H6: PV25 | I6: camille.queinnec@universite-paris-saclay.fr | J6: https://www.universite-paris-saclay.fr/parcours-de-formation-valorisation-de-projets-de-recherche-innovants-du-concept-au-marche | K6: Fondateur | L6: CQ
A7: 5 | B7: ERC | C7: Mette Skadstraat Consultante pour la formation et préparation à l'ERC | D7: Webinaires, préparation aux oraux, relectures de documents, oraux blancs | E7: Yellow research | F7: Consultant | G7: Externe | H7: Amanda Nieto | J7: https://www.yellowresearch.nl/ | K7: Autre
A8: 6 | B8: Éthique et innovation : comment intégrer l'IA Act dans sa stratégie d'innovation ? | C8: AI ACT Cette session en partenariat avec le Hub France IA vise à fournir aux TPE, PME et ETI les outils essentiels pour se lancer dans l'aventure de l'IA avec confiance. | D8: A créer | E8: Hub France IA | F8: Responsable des affaires européennes et réglementaires | G8: Externe | H8: Chloé PLÉDEL | J8: BIG BPI Masterclass | K8: Autre
A9: 7 | B9: Éthique et innovation : comment intégrer l'IA Act dans sa stratégie d'innovation ? | C9: Cette session en partenariat avec le Hub France IA vise à fournir aux TPE, PME et ETI les outils essentiels pour se lancer dans l'aventure de l'IA avec confiance. | D9: A créer | E9: Bpifrance | F9: Responsable de l'acceleration IA - Direction du digital | H9: Pierre JARRIJON | J9: https://evenements.bpifrance.fr/big-2024/fr/onlinesession/8e167e6f-812d-ef11-86c3-002248863087 | K9: Autre
A10: 8 | B10: Master / Licence | C10: Droit du numérique et de l’espace/ Droit de l’innovation et propriété industrielle/Droit, Sciences & Innovation | D10: En attente infos | E10: Université Paris-Saclay | F10: Vice-président Patrimoine & Infrastructures/Doyen honoraire/ Chercheur au Cerdi | G10: Interne | H10: Antoine Latreille | I10: antoine.latreille@universite-paris-saclay.fr
A11: 9 | B11: Créer un cours sur FUN | C11: Création de MOOC et SPOOC France Universités Numérique | E11: France Universités Numérique | F11: Directeur technique et chef de projet | G11: Externe | H11: Cédric Bassette | I11: cedric.bassette@fun-mooc.fr | J11: https://www.fun-mooc.fr/fr/ | K11: Autre
A12: 10 | B12: Doctorants | C12: Médiation scientifique | D12: jours / rémunérés sur le même barême 32 jours au plus | E12: Université Paris-Saclay | F12: Doctorants étudiants
A13: 11 | B13: =+'Formations PUI'!C7 -> Créer sa landing page sans savoir coder en 48 heures | D13: A créer | E13: =+'Formations PUI'!D7 -> Diogale | G13: Externe | H13: =+'Formations PUI'!F7 -> Animé par Doudou Diof | I13: Contacter Sophie Dondeyne DFR | K13: Autre
A14: 12 | B14: =+'Formations PUI'!C8 -> Quelle idée pour créer ton entreprise ? | D14: A créer | E14: =+'Formations PUI'!D8 -> Innowide | G14: Externe | H14: =+'Formations PUI'!F8 -> Animé par Damien Cuoq | I14: Contacter Sophie Dondeyne DFR | K14: Autre
A15: 13 | B15: =+'Formations PUI'!C9 -> De l'idée à l'action : concevoir et lancer votre startup | D15: A créer | E15: =+'Formations PUI'!D9 -> Start in Saclay | G15: Interne | H15: =+'Formations PUI'!F9 -> 0 | I15: Contacter Sophie Dondeyne DFR | K15: Fondateur
A16: 14 | B16: =+'Formations PUI'!C10 -> Les conseils pour avoir un pitch convaincant | D16: A créer | E16: =+'Formations PUI'!D10 -> Association EGEE | G16: Externe | H16: =+'Formations PUI'!F10 -> 0 | I16: Contacter Sophie Dondeyne DFR | K16: Autre
A17: 15 | B17: =+'Formations PUI'!C11 -> Les outils à connaitre pour son projet d'entreprise | D17: A créer | E17: =+'Formations PUI'!D11 -> Design Spot | G17: Interne | H17: =+'Formations PUI'!F11 -> Annimé par Yoann Montenot | I17: Contacter Sophie Dondeyne DFR | K17: Fondateur
A18: 16 | B18: =+'Formations PUI'!C12 -> Le modéle économique | D18: A créer | E18: =+'Formations PUI'!D12 -> Université Paris-Saclay | G18: Interne | H18: =+'Formations PUI'!F12 -> 0 | I18: Contacter Sophie Dondeyne DFR | K18: Fondateur
A19: 17 | B19: =+'Formations PUI'!C13 -> Entreprendre en deeptech : défis et opportunités | D19: A créer | E19: =+'Formations PUI'!D13 -> Start in Saclay | G19: Interne | H19: =+'Formations PUI'!F13 -> 0 | I19: Contacter Sophie Dondeyne DFR | K19: Fondateur
A20: 18 | B20: =+'Formations PUI'!C14 -> Aide à la recherche documentaire pour réaliser une étude de marché | D20: A créer | E20: =+'Formations PUI'!D14 -> Université Paris-Saclay | G20: Interne | H20: =+'Formations PUI'!F14 -> Animé par Imelda Lemoing | I20: Contacter Sophie Dondeyne DFR | K20: Fondateur
A21: 19 | B21: =+'Formations PUI'!C15 -> Débuter sans argent | D21: A créer | E21: =+'Formations PUI'!D15 -> Graines de conseil | G21: Externe | H21: =+'Formations PUI'!F15 -> Animé par Bertrand De Saint Viance | I21: Contacter Sophie Dondeyne DFR | K21: Autre
A22: 20 | B22: =+'Formations PUI'!C16 -> Les étapes de la création d'entreprise | D22: A créer | E22: =+'Formations PUI'!D16 -> Vallée Sud Grand Paris | G22: Externe | H22: =+'Formations PUI'!F16 -> Animé par Farrouk Khenoussi | I22: Contacter Sophie Dondeyne DFR | K22: Autre
A23: 21 | B23: =+'Formations PUI'!C17 -> Le développement et la construction de sa stratégie sur la propriété intelectuelle | D23: A créer | E23: =+'Formations PUI'!D17 -> INPI | G23: Externe | H23: =+'Formations PUI'!F17 -> Animé par Sophie Djega Mariadassou | I23: Contacter Sophie Dondeyne DFR | K23: Autre
A24: 22 | B24: =+'Formations PUI'!C18 -> Accélérateurs et incubateurs : catalyseurs de réussite | D24: A créer | E24: =+'Formations PUI'!D18 -> Start in Saclay | G24: Interne | H24: =+'Formations PUI'!F18 -> 0 | I24: Contacter Sophie Dondeyne DFR | K24: Fondateur
... A26: 24 | B26: =+'Formations PUI'!C20 -> Accélérer la croissance : les clés pour réussir sa levée de fonds | D26: A créer | E26: =+'Formations PUI'!D20 -> Start in Saclay | G26: Interne | H26: =+'Formations PUI'!F20 -> 0 | I26: Contacter Sophie Dondeyne DFR | K26: Fondateur
A27: 25 | B27: =+'Formations PUI'!C21 -> Les stratégies marketing | D27: A créer | E27: =+'Formations PUI'!D21 -> Association EGEE | G27: Externe | H27: =+'Formations PUI'!F21 -> Animé par Jacques Bonnement | I27: Contacter Sophie Dondeyne DFR
A28: 26 | B28: =+'Formations PUI'!C22 -> Startups à impact : entreprendre pour un monde meilleur | D28: A créer | E28: =+'Formations PUI'!D22 -> Start in Saclay | G28: Interne | H28: =+'Formations PUI'!F22 -> 0 | I28: Contacter Sophie Dondeyne DFR | K28: Fondateur
A29: 27 | B29: =+'Formations PUI'!C23 -> Entreprendre autrement : les modéles d'entrepreneuriat alternatifs | D29: A créer | E29: =+'Formations PUI'!D23 -> Start in Saclay | G29: Interne | H29: =+'Formations PUI'!F23 -> 0 | I29: Contacter Sophie Dondeyne DFR | K29: Fondateur
A30: 28 | B30: =+'Formations PUI'!C24 -> L'aide au financement pour créer son entreprise | D30: A créer | E30: =+'Formations PUI'!D24 -> France Active | G30: Externe | H30: =+'Formations PUI'!F24 -> Animé par Chérif Abbou | I30: Contacter Sophie Dondeyne DFR | K30: Autre
A31: 29 | B31: Serious game: l'année de l'innovation | D31: Avec de droits de licence d'utilisation | E31: Centrale Supelec | G31: Interne | H31: Bernard Yannou
A32: 30 | B32: Ikigai - Games for Citizens | C32: Innovation par les jeux | D32: A créer | E32: Ikigai - Games for Citizens | F32: Responsable de formation, d'animation de communauté et de prospection | G32: Externe | H32: Florian Delcourt | I32: formation.animation@ikigai.games | J32: https://www.gfc.ikigai.games/ | K32: Autre | L32: tel 0620853103
A33: 31 | B33: Design Thiking | C33: Atelier spécifique sur le Design Thinking l'Atelier Universel | D33: Atelier | E33: L'Atelier Universel | G33: Externe | H33: Xavier Auffret | I33: xavier.auffret@atelier-universel.com | J33: atelier-universel.com
A34: 32 | B34: Design Thiking | C34: Le Design Thinking légèrement abordé lors de l'atelier "c'est quoi le design ?". | D34: Atelier | E34: Design Spot | F34: Directeur Design Spot | G34: Interne | H34: Yoann Montenot | I34: yoann.montenot@universite-paris-saclay.fr
